<?xml version="1.0" encoding="UTF-8"?>
<!-- Generated by org.testng.reporters.JUnitReportReporter -->
<testsuite hostname="SHMOTAMA-XGVPB" name="com.vts.tests.Test01_UserManagement" tests="9" failures="0" timestamp="5 Jan 2016 11:54:11 GMT" time="89.717" errors="1">
  <testcase name="test07_CancelEditRow" time="6.858" classname="com.vts.tests.Test01_UserManagement"/>
  <testcase name="test06_EditRowBlankData" time="3.194" classname="com.vts.tests.Test01_UserManagement"/>
  <testcase name="test09_DeleteRow" time="19.895" classname="com.vts.tests.Test01_UserManagement"/>
  <testcase name="test02_addDuplicateUser" time="4.316" classname="com.vts.tests.Test01_UserManagement"/>
  <testcase name="test04_CancelAddRow" time="5.798" classname="com.vts.tests.Test01_UserManagement"/>
  <testcase name="test08_CancelDeleteRow" time="10.471" classname="com.vts.tests.Test01_UserManagement"/>
  <testcase name="test05_EditRowValidData" time="10.807" classname="com.vts.tests.Test01_UserManagement"/>
  <testcase name="test03_AddRowBlankData" time="3.193" classname="com.vts.tests.Test01_UserManagement"/>
  <testcase name="test01_addUser" time="25.185" classname="com.vts.tests.Test01_UserManagement">
    <error type="java.lang.AssertionError" message="expected [User saved successfully.] but found [Could not retrieve Message from toaster]">
      <![CDATA[java.lang.AssertionError: expected [User saved successfully.] but found [Could not retrieve Message from toaster]
	at org.testng.Assert.fail(Assert.java:94)
	at org.testng.Assert.failNotEquals(Assert.java:494)
	at org.testng.Assert.assertEquals(Assert.java:123)
	at org.testng.Assert.assertEquals(Assert.java:176)
	at org.testng.Assert.assertEquals(Assert.java:186)
	at com.vts.tests.Test01_UserManagement.test01_addUser(Test01_UserManagement.java:62)
	at sun.reflect.NativeMethodAccessorImpl.invoke0(Native Method)
	at sun.reflect.NativeMethodAccessorImpl.invoke(Unknown Source)
	at sun.reflect.DelegatingMethodAccessorImpl.invoke(Unknown Source)
	at java.lang.reflect.Method.invoke(Unknown Source)
	at org.testng.internal.MethodInvocationHelper.invokeMethod(MethodInvocationHelper.java:84)
	at org.testng.internal.Invoker.invokeMethod(Invoker.java:714)
	at org.testng.internal.Invoker.invokeTestMethod(Invoker.java:901)
	at org.testng.internal.Invoker.invokeTestMethods(Invoker.java:1231)
	at org.testng.internal.TestMethodWorker.invokeTestMethods(TestMethodWorker.java:127)
	at org.testng.internal.TestMethodWorker.run(TestMethodWorker.java:111)
	at org.testng.TestRunner.privateRun(TestRunner.java:767)
	at org.testng.TestRunner.run(TestRunner.java:617)
	at org.testng.SuiteRunner.runTest(SuiteRunner.java:348)
	at org.testng.SuiteRunner.runSequentially(SuiteRunner.java:343)
	at org.testng.SuiteRunner.privateRun(SuiteRunner.java:305)
	at org.testng.SuiteRunner.run(SuiteRunner.java:254)
	at org.testng.SuiteRunnerWorker.runSuite(SuiteRunnerWorker.java:52)
	at org.testng.SuiteRunnerWorker.run(SuiteRunnerWorker.java:86)
	at org.testng.TestNG.runSuitesSequentially(TestNG.java:1224)
	at org.testng.TestNG.runSuitesLocally(TestNG.java:1149)
	at org.testng.TestNG.run(TestNG.java:1057)
	at org.testng.remote.RemoteTestNG.run(RemoteTestNG.java:111)
	at org.testng.remote.RemoteTestNG.initAndRun(RemoteTestNG.java:204)
	at org.testng.remote.RemoteTestNG.main(RemoteTestNG.java:175)
]]>
    </error>
  </testcase> <!-- test01_addUser -->
</testsuite> <!-- com.vts.tests.Test01_UserManagement -->
